Workbook

Sheet 출고요청서
D1: 착오수량 | E1: =(SUM(E2:E4))-E13 -> 0 | F1: =(SUM(F2:F4))-F13 -> 0 | G1: =(SUM(G2:G4))-G13 -> 0 | H1: =(SUM(H2:H4))-H13 -> 0 | N1: =(SUM(N2:N4))-N13 -> 0 | O1: =SUM(E1:H1) -> 0 | Q1: =1791-1583 -> 208
O2: =SUM(E2:H2) -> 0
D3: 출고완료
D4: 패킹 입고수량
E5: =E63 -> -18 | F5: =F63 -> -136 | G5: =G63 -> -182 | H5: =H63 -> -108 | N5: =N63 -> 5 | O5: =O63 -> -439
E9: =#REF! -> #REF! | F9: =#REF! -> #REF! | G9: =#REF! -> #REF! | H9: =#REF! -> #REF! | O9: =#REF! -> #REF!
E10: =SUM(#REF!) -> #REF! | F10: =SUM(#REF!) -> #REF! | G10: =SUM(#REF!) -> #REF! | H10: =SUM(#REF!) -> #REF! | O10: =SUM(#REF!) -> #REF!
D11: 오션 | E11: =E9-SUM(E36:E38) -> #REF! | F11: =F9-SUM(F36:F38) -> #REF! | G11: =G9-SUM(G36:G38) -> #REF! | H11: =H9-SUM(H36:H38) -> #REF!
D12: 에어 | E12: =E10-SUM(E33:E34) -> #REF! | F12: =F10-SUM(F33:F34) -> #REF! | G12: =G10-SUM(G33:G34) -> #REF! | H12: =H10-SUM(H33:H34) -> #REF!
B14: 46181 | N14: 냉동 | O14: 합계 | P14: 비고
E15: 망고스틴 5kg
B16: 생산 | C16: 통관일자 | D16: B/L No. | E16: 4 | F16: 5 | G16: 6 | H16: 7 | J16: 14 | K16: 16 | N16: 4수
A17: 1 | N17: 5 | O17: =SUM(E17:N17) -> 5 | Z17: 1016 386 9 345
A18: 8 | D18: 폐기 78개 | O18: =SUM(E18:N18) -> 0
A19: 9 | O19: =SUM(E19:N19) -> 0
A20: 10 | O20: =SUM(E20:N20) -> 0
A21: 11 | O21: =SUM(E21:N21) -> 0
A22: 12 | O22: =SUM(E22:N22) -> 0
A23: 13 | O23: =SUM(E23:N23) -> 0
A24: 14 | O24: =SUM(E24:N24) -> 0
O25: =SUM(E25:N25) -> 0
O26: =SUM(E26:N26) -> 0
O27: =SUM(E27:N27) -> 0
O28: =SUM(E28:N28) -> 0
A29: 15 | O29: =SUM(E29:N29) -> 0
E30: =SUM(E17:E29) -> 0 | F30: =SUM(F17:F29) -> 0 | G30: =SUM(G17:G29) -> 0 | H30: =SUM(H17:H29) -> 0 | I30: =SUM(I17:I29) -> 0 | J30: =SUM(J17:J29) -> 0 | K30: =SUM(K17:K29) -> 0 | L30: =SUM(L17:L29) -> 0 | ... N30: =SUM(N17:N29) -> 5 | O30: =SUM(E30:N30) -> 5
E31: =SUM(E33:E54) -> 0 | F31: =SUM(F33:F54) -> 0 | G31: =SUM(G33:G54) -> 0 | H31: =SUM(H33:H54) -> 0 | I31: =SUM(I33:I57) -> 0 | J31: =SUM(J33:J57) -> 0 | K31: =SUM(K33:K57) -> 0 | L31: =SUM(L33:L57) -> 0 | M31: =SUM(M33:M57) -> 0 | N31: 0 | O31: =SUM(E31:N31) -> 0 | Q31: 태국망고 5kg | R31: 태국망고5kg | S31: 대만 | U31: 파인애플10kg | V31: 파인애플10kg | W31: 두리안
E32: =E30-E31 -> 0 | F32: =F30-F31 -> 0 | G32: =G30-G31 -> 0 | H32: =H30-H31 -> 0 | I32: =I30-I31 -> 0 | J32: =J30-J31 -> 0 | K32: =K30-K31 -> 0 | L32: =L30-L31 -> 0 | ... N32: =N30-N31 -> 5 | O32: =SUM(E32:N32) -> 5 | Q32: A급합계 | R32: B급합계 | S32: A급합계 | T32: B급합계 | U32: A급합계 | V32: A급합계 | W32: A급합계 | X32: 주소 | Y32: 담당자 | Z32: 전화번호
A33: 1 | B33: 46174 | C33: 검역로스 | D33: 검역로스 | O33: =SUM(E33:N33) -> 0 | Q33: =SUM(E33:H33) -> 0 | R33: =SUM(#REF!) -> #REF! | S33: =SUM(#REF!) -> #REF! | T33: =SUM(#REF!) -> #REF! | U33: =SUM(#REF!) -> #REF! | V33: =SUM(#REF!) -> #REF! | W33: =SUM(N33:N33) -> 0 | X33: =IFERROR(VLOOKUP(C33&D33,가락!$B$2:$E$498,2,FALSE),"") | Y33: =IFERROR(VLOOKUP(C33&D33,가락!B1:$E$498,3,FALSE),"") | Z33: =IFERROR(VLOOKUP(C33&D33,가락!B1:$E$498,4,FALSE),"")
B34: 46181 | C34: 강서 | D34: 성심 | O34: =SUM(E34:N34) -> 0
B35: 46181 | C35: 안양 | D35: 푸르미 | O35: =SUM(E35:N35) -> 0
A36: 10 | B36: 46181 | C36: 천안 | D36: 천안영풍 | O36: =SUM(E36:N36) -> 0 | Q36: =SUM(E36:H36) -> 0 | R36: =SUM(#REF!) -> #REF! | S36: =SUM(#REF!) -> #REF! | T36: =SUM(#REF!) -> #REF! | U36: =SUM(#REF!) -> #REF! | V36: =SUM(#REF!) -> #REF! | W36: =SUM(N36:N36) -> 0 | X36: =IFERROR(VLOOKUP(#REF!&#REF!,가락!$B$2:$E$498,2,FALSE),"") | Y36: =IFERROR(VLOOKUP(#REF!&#REF!,가락!B13:$E$498,3,FALSE),"") | Z36: =IFERROR(VLOOKUP(#REF!&#REF!,가락!B13:$E$498,4,FALSE),"")
A37: 11 | B37: 46181 | C37: 가락 | D37: 한라 | O37: =SUM(E37:N37) -> 0 | Q37: =SUM(E37:H37) -> 0 | R37: =SUM(#REF!) -> #REF! | S37: =SUM(#REF!) -> #REF! | T37: =SUM(#REF!) -> #REF! | U37: =SUM(#REF!) -> #REF! | V37: =SUM(#REF!) -> #REF! | W37: =SUM(N37:N37) -> 0 | Y37: =IFERROR(VLOOKUP(D39&#REF!,가락!B15:$E$498,3,FALSE),"") | Z37: =IFERROR(VLOOKUP(D39&#REF!,가락!B15:$E$498,4,FALSE),"")
A38: 12 | B38: 46181 | C38: 진주 | D38: 진주NF | O38: =SUM(E38:N38) -> 0 | Q38: =SUM(E38:H38) -> 0 | R38: =SUM(#REF!) -> #REF! | S38: =SUM(#REF!) -> #REF! | T38: =SUM(#REF!) -> #REF! | U38: =SUM(#REF!) -> #REF! | V38: =SUM(#REF!) -> #REF! | W38: =SUM(N38:N38) -> 0 | X38: =IFERROR(VLOOKUP(#REF!&#REF!,가락!$B$2:$E$498,2,FALSE),"") | Y38: =IFERROR(VLOOKUP(#REF!&#REF!,가락!B16:$E$498,3,FALSE),"") | Z38: =IFERROR(VLOOKUP(#REF!&#REF!,가락!B16:$E$498,4,FALSE),"")
A39: 13 | B39: 46181 | C39: 대전 | D39: 사우스코어 | O39: =SUM(E39:N39) -> 0 | Q39: =SUM(E39:H39) -> 0 | R39: =SUM(#REF!) -> #REF! | S39: =SUM(#REF!) -> #REF! | T39: =SUM(#REF!) -> #REF! | U39: =SUM(#REF!) -> #REF! | V39: =SUM(#REF!) -> #REF! | W39: =SUM(N39:N39) -> 0 | X39: =IFERROR(VLOOKUP(#REF!&C39,가락!$B$2:$E$498,2,FALSE),"") | Y39: =IFERROR(VLOOKUP(#REF!&C39,가락!B18:$E$498,3,FALSE),"") | Z39: =IFERROR(VLOOKUP(#REF!&C39,가락!B18:$E$498,4,FALSE),"")
O40: =SUM(E40:N40) -> 0
O41: =SUM(E41:N41) -> 0
O42: =SUM(E42:N42) -> 0
A43: 18 | O43: =SUM(E43:N43) -> 0 | Q43: =SUM(E43:H43) -> 0 | R43: =SUM(#REF!) -> #REF! | S43: =SUM(#REF!) -> #REF! | T43: =SUM(#REF!) -> #REF! | U43: =SUM(#REF!) -> #REF! | V43: =SUM(#REF!) -> #REF! | W43: =SUM(N43:N43) -> 0 | X43: =IFERROR(VLOOKUP(C48&D43,가락!$B$2:$E$498,2,FALSE),"") | Y43: =IFERROR(VLOOKUP(C48&D43,가락!B24:$E$498,3,FALSE),"") | Z43: =IFERROR(VLOOKUP(C48&D43,가락!B24:$E$498,4,FALSE),"")
A44: 20 | O44: =SUM(E44:N44) -> 0 | Q44: =SUM(E44:H44) -> 0 | R44: =SUM(#REF!) -> #REF! | S44: =SUM(#REF!) -> #REF! | T44: =SUM(#REF!) -> #REF! | U44: =SUM(#REF!) -> #REF! | V44: =SUM(#REF!) -> #REF! | W44: =SUM(N44:N44) -> 0 | X44: =IFERROR(VLOOKUP(C44&D44,가락!$B$2:$E$498,2,FALSE),"") | Y44: =IFERROR(VLOOKUP(C44&D44,가락!B26:$E$498,3,FALSE),"") | Z44: =IFERROR(VLOOKUP(C44&D44,가락!B26:$E$498,4,FALSE),"")
...

Sheet 가락
A1: 지역 | B1: 거래처 | C1: 주소 | D1: 담당자 | E1: 연락처
A2: 논산 | B2: 논산논산청과 | C2: 충남 논산시 취암동 504 | E2: 011-456-1007
A3: GS | B3: gs양산물류센터 | C3: 경남 양산시 다방동 98-1 | D3: 하역담당 | E3: 010-4285-0057
A4: 가락 | B4: 가락농협신양플러스 | C4: 서울시 송파구 양재대로 932 (가락동)
A5: 가락 | B5: 가락동화성은 | C5: 서울시 송파구 양재대로 932 (가락동)
A6: 가락 | B6: 가락서울가락청과 | C6: 서울시 송파구 양재대로 932 (가락동)
A7: 가락 | B7: 가락중앙중앙청과 | C7: 서울시 송파구 양재대로 932 (가락동)
A8: 가락 | B8: 가락한국송화 | C8: 서울시 송파구 양재대로 932 (가락동)
A9: 가락농협 | B9: 가락농협경운 | C9: 서울시 송파구 양재대로 932 (가락동)
A10: 가락농협 | B10: 가락농협대일후르츠 | C10: 서울시 송파구 양재대로 932 (가락동)
A11: 강서 | B11: 강서선인농산 | C11: 서울시 강서구 발산로 40 강서농수산물 도매시장 A-3호 (02-2640-9903) | D11: 백승열 | E11: 010-8746-6936
A12: 강서 | B12: 강서수명산 | C12: 서울시 강서구 외발산동 216-18 | E12: 010-2841-9420
A13: 경기 | B13: 경기황금물산2지점 | C13: 신천동 879-6 | E13: 010-2298-3234
A14: 광명 | B14: 광명광명유통 | C14: 광명시 가학동 335번지 | E14: 010-5535-9882
A15: 광주 | B15: 광주누리원 | C15: 광주광역시 북구 첨단연신로4 누리원, 간판 두개 누리원 또는 광명데이콤 | E15: 010-7112-3824
A16: 광주 | B16: 광주광주원협 | C16: 광주광역시 북구 각화동 437-3 | E16: 062-250-7000
A17: 광주 | B17: 광주광주농협 | C17: 광주광역시 서구 매월동 954
A18: 광주 | B18: 광주두레청과 | C18: 광주광역시 서구 매월동 954 | E18: 062-655-6688
A19: 광주 | B19: 광주서부농협 | C19: 광주광역시 서구 매월동 954 | E19: 062-651-4900
A20: 광주매월 | B20: 광주매월장보남 | C20: 광주 서구 매월동 952-16번지 | E20: 010-2606-9780
A21: 구리 | B21: 구리구리청과 | C21: 경기도 구리시 도매시장로 68(인창동) | E21: 031-560-6182
A22: 김포 | B22: 김포광명유통 | C22: 김포공항 | E22: 010-8964-4711
A23: 김포 | B23: 김포문명길 | C23: 경기도 김포시 한강8로 15, 한강센트럴블루힐 505동 140호 | E23: 010-8865-8255
A24: 남양주 | B24: 남양주비티원 | C24: 남양주시 진접읍 연평리 233 | E24: 010-7299-8293
A25: 남양주 | B25: 남양주인우마케팅 | C25: 경기도 남양주시 진접읍 연평리 458-5 인우 | E25: 010-2110-9545
A26: 논산 | B26: 논산논산피알 | C26: 충남 논산시 계백로 918(논산 KT전화국 옆) | E26: 010-5514-1244
A27: 논산 | B27: 논산황산청과 | C27: 충남 논산시 취암동 504 | D27: 경매사님 | E27: 010-7730-8082
A28: 대구 | B28: 대구대구경북원예농협 | C28: 매천동 527-3번지 | E28: 053-312-1792
A29: 대구 | B29: 대구대구만성 | C29: 대구 북구 관음동 6-7번지 | E29: 010-2530-1237
A30: 대구 | B30: 대구백운농산 | C30: 매천동 167-3 | E30: 010-3521-1683
A31: 대구 | B31: 대구효성청과 | C31: 대구광역시 북구 매천동 537-3번지 | D31: 정상록 부장 | E31: 010-3812-4489
A32: 대전 | B32: 대전대성청과 | C32: 오정동 시장 앞 | E32: 042-621-7694
A33: 대전 | B33: 대전대전농협 | C33: 대전광역시 대덕구 한밭대로 987(042-624-7781) | D33: 류재명 과장 | E33: 010-4410-8259
A34: 대전 | B34: 대전대전원협 | C34: 유성구 노은동로 33
A35: 대전 | B35: 대전대전중앙 | C35: 노은동 농산물시장
A36: 동탄 | B36: 동탄채과원 | C36: 화성시 동탄면 동타산단3길 20-5(방교리)
A37: 마산 | B37: 마산수지글로벌 | C37: 경남 창원시 마산회원구 내서읍 중리 750번지, 마산청과 77번
A38: 목포 | B38: 목포금성 | C38: 목포시 대양동1187-5번지 | E38: 010-9435-3466
A39: 목포 | B39: 목포목포원협 | C39: 전라남도 목포시 상동 250-5 | D39: 이명규경매사 | E39: 010-5400-5455
A40: 목포 | B40: 목포보신상사 | C40: 전남 무안군 일로읍 산정리 768-1 | E40: 010-4624-2761
...

Sheet Sheet1
C4: 8 | D4: 9 | E4: 10 | F4: 12 | G4: 14 | H4: 16 | I4: 18 | J4: 20 | K4: 22 | M4: 16
B5: 5 | E5: =+B5/E4 -> 0.5 | F5: =+B5/F4 -> 0.41666667 | G5: =+B5/G4 -> 0.35714286 | H5: =+B5/H4 -> 0.3125 | I5: =+B5/I4 -> 0.27777778 | J5: =+B5/J4 -> 0.25 | K5: =+B5/K4 -> 0.22727273
B6: 4 | C6: =B6/C4 -> 0.5 | D6: =+B6/D4 -> 0.44444444 | E6: =+B6/E4 -> 0.4 | F6: =+B6/F4 -> 0.33333333 | G6: =B6/G4 -> 0.28571429 | H6: =B6/H4 -> 0.25 | I6: =B6/I4 -> 0.22222222 | J6: =+B6/J4 -> 0.2 | K6: =+B6/K4 -> 0.18181818
